{
 "cells": [
  {
   "cell_type": "code",
   "execution_count": null,
   "metadata": {},
   "outputs": [
    {
     "name": "stderr",
     "output_type": "stream",
     "text": [
      "Using TensorFlow backend.\n",
      "ERROR:root:Internal Python error in the inspect module.\n",
      "Below is the traceback from this internal error.\n",
      "\n",
      "ERROR:root:Internal Python error in the inspect module.\n",
      "Below is the traceback from this internal error.\n",
      "\n",
      "--- Logging error ---\n",
      "--- Logging error ---\n",
      "--- Logging error ---\n",
      "--- Logging error ---\n",
      "--- Logging error ---\n",
      "Error in sys.excepthook:\n",
      "Traceback (most recent call last):\n",
      "  File \"/usr/lib/python3.7/linecache.py\", line 47, in getlines\n",
      "    return updatecache(filename, module_globals)\n",
      "  File \"/usr/lib/python3.7/linecache.py\", line 137, in updatecache\n",
      "    lines = fp.readlines()\n",
      "  File \"/usr/lib/python3.7/codecs.py\", line 322, in decode\n",
      "    (result, consumed) = self._buffer_decode(data, self.errors, final)\n",
      "UnicodeDecodeError: 'utf-8' codec can't decode byte 0xac in position 4128: invalid start byte\n",
      "\n",
      "Original exception was:\n",
      "Traceback (most recent call last):\n",
      "  File \"/usr/local/lib/python3.7/dist-packages/IPython/core/interactiveshell.py\", line 3331, in run_code\n",
      "    exec(code_obj, self.user_global_ns, self.user_ns)\n",
      "  File \"<ipython-input-28-23ceb3acf5fb>\", line 15, in <module>\n",
      "  File \"/home/pi/.local/lib/python3.7/site-packages/keras/__init__.py\", line 3, in <module>\n",
      "    from . import utils\n",
      "  File \"/home/pi/.local/lib/python3.7/site-packages/keras/utils/__init__.py\", line 6, in <module>\n",
      "    from . import conv_utils\n",
      "  File \"/home/pi/.local/lib/python3.7/site-packages/keras/utils/conv_utils.py\", line 9, in <module>\n",
      "    from .. import backend as K\n",
      "  File \"/home/pi/.local/lib/python3.7/site-packages/keras/backend/__init__.py\", line 1, in <module>\n",
      "    from .load_backend import epsilon\n",
      "  File \"/home/pi/.local/lib/python3.7/site-packages/keras/backend/load_backend.py\", line 90, in <module>\n",
      "    from .tensorflow_backend import *\n",
      "  File \"/home/pi/.local/lib/python3.7/site-packages/keras/backend/tensorflow_backend.py\", line 5, in <module>\n",
      "    import tensorflow as tf\n",
      "  File \"/home/pi/.local/lib/python3.7/site-packages/tensorflow/__init__.py\", line 98, in <module>\n",
      "    from tensorflow_core import *\n",
      "  File \"/home/pi/.local/lib/python3.7/site-packages/tensorflow_core/__init__.py\", line 28, in <module>\n",
      "    modules/gapi/CMakeFiles/opencv_perf_gapi.dir/perf/perf_main.cpp.o: ../modules/ts/include/opencv2/ts/ts_ext.hpp\n",
      "  File \"<frozen importlib._bootstrap>\", line 1019, in _handle_fromlist\n",
      "  File \"/home/pi/.local/lib/python3.7/site-packages/tensorflow/__init__.py\", line 50, in __getattr__\n",
      "    module = self._load()\n",
      "  File \"/home/pi/.local/lib/python3.7/site-packages/tensorflow/__init__.py\", line 44, in _load\n",
      "    module = _importlib.import_module(self.__name__)\n",
      "  File \"/usr/lib/python3.7/importlib/__init__.py\", line 127, in import_module\n",
      "    return _bootstrap._gcd_import(name[level:], package, level)\n",
      "  File \"/home/pi/.local/lib/python3.7/site-packages/tensorflow_core/python/__init__.py\", line 78, in <module>\n",
      "    from tensorflow.python.ops.standard_ops import *\n",
      "  File \"/home/pi/.local/lib/python3.7/site-packages/tensorflow_core/python/ops/standard_ops.py\", line 25, in <module>\n",
      "    from tensorflow.python import autograph\n",
      "  File \"/home/pi/.local/lib/python3.7/site-packages/tensorflow_core/python/autograph/__init__.py\", line 35, in <module>\n",
      "    from tensorflow.python.autograph import operators\n",
      "  File \"/home/pi/.local/lib/python3.7/site-packages/tensorflow_core/python/autograph/__init__.py\", line 37, in <module>\n",
      "    from tensorflow.python.autograph.core.converter import ConversionOptions\n",
      "  File \"/home/pi/.local/lib/python3.7/site-packages/tensorflow_core/python/autograph/core/converter.py\", line 69, in <module>\n",
      "    from tensorflow.python.autograph.pyct import anno\n",
      "  File \"/home/pi/.local/lib/python3.7/site-packages/tensorflow_core/python/autograph/pyct/anno.py\", line 27, in <module>\n",
      "    import gast\n",
      "  File \"/home/pi/.local/lib/python3.7/site-packages/gast/__init__.py\", line 1\n",
      "    /*\n",
      "    ^\n",
      "SyntaxError: invalid syntax\n",
      "\n",
      "During handling of the above exception, another exception occurred:\n",
      "\n",
      "Traceback (most recent call last):\n",
      "  File \"/usr/local/lib/python3.7/dist-packages/IPython/core/interactiveshell.py\", line 3254, in run_ast_nodes\n",
      "    if (await self.run_code(code, result,  async_=asy)):\n",
      "  File \"/usr/local/lib/python3.7/dist-packages/IPython/core/interactiveshell.py\", line 3348, in run_code\n",
      "    self.showtraceback(running_compiled_code=True)\n",
      "  File \"/usr/local/lib/python3.7/dist-packages/IPython/core/interactiveshell.py\", line 2030, in showtraceback\n",
      "    self.showsyntaxerror(filename, running_compiled_code)\n",
      "  File \"/usr/local/lib/python3.7/dist-packages/IPython/core/interactiveshell.py\", line 2091, in showsyntaxerror\n",
      "    elist = traceback.extract_tb(last_traceback) if running_compiled_code else []\n",
      "  File \"/usr/lib/python3.7/traceback.py\", line 72, in extract_tb\n",
      "    return StackSummary.extract(walk_tb(tb), limit=limit)\n",
      "  File \"/usr/lib/python3.7/traceback.py\", line 363, in extract\n",
      "    f.line\n",
      "  File \"/usr/lib/python3.7/traceback.py\", line 285, in line\n",
      "    self._line = linecache.getline(self.filename, self.lineno).strip()\n",
      "  File \"/usr/lib/python3.7/linecache.py\", line 16, in getline\n",
      "    lines = getlines(filename, module_globals)\n",
      "  File \"/usr/lib/python3.7/linecache.py\", line 47, in getlines\n",
      "    return updatecache(filename, module_globals)\n",
      "  File \"/usr/lib/python3.7/linecache.py\", line 137, in updatecache\n",
      "    lines = fp.readlines()\n",
      "  File \"/usr/lib/python3.7/codecs.py\", line 322, in decode\n",
      "    (result, consumed) = self._buffer_decode(data, self.errors, final)\n",
      "UnicodeDecodeError: 'utf-8' codec can't decode byte 0xac in position 4128: invalid start byte\n",
      "\n",
      "During handling of the above exception, another exception occurred:\n",
      "\n",
      "Traceback (most recent call last):\n",
      "  File \"/usr/local/lib/python3.7/dist-packages/IPython/core/interactiveshell.py\", line 2044, in showtraceback\n",
      "    stb = value._render_traceback_()\n",
      "AttributeError: 'UnicodeDecodeError' object has no attribute '_render_traceback_'\n",
      "\n",
      "During handling of the above exception, another exception occurred:\n",
      "\n",
      "Traceback (most recent call last):\n",
      "  File \"/usr/local/lib/python3.7/dist-packages/IPython/core/ultratb.py\", line 1148, in get_records\n",
      "    return _fixed_getinnerframes(etb, number_of_lines_of_context, tb_offset)\n",
      "  File \"/usr/local/lib/python3.7/dist-packages/IPython/core/ultratb.py\", line 316, in wrapped\n",
      "    return f(*args, **kwargs)\n",
      "  File \"/usr/local/lib/python3.7/dist-packages/IPython/core/ultratb.py\", line 350, in _fixed_getinnerframes\n",
      "    records = fix_frame_records_filenames(inspect.getinnerframes(etb, context))\n",
      "  File \"/usr/lib/python3.7/inspect.py\", line 1502, in getinnerframes\n",
      "    frameinfo = (tb.tb_frame,) + getframeinfo(tb, context)\n",
      "  File \"/usr/lib/python3.7/inspect.py\", line 1460, in getframeinfo\n",
      "    filename = getsourcefile(frame) or getfile(frame)\n",
      "  File \"/usr/lib/python3.7/inspect.py\", line 696, in getsourcefile\n",
      "    if getattr(getmodule(object, filename), '__loader__', None) is not None:\n",
      "  File \"/usr/lib/python3.7/inspect.py\", line 733, in getmodule\n",
      "    if ismodule(module) and hasattr(module, '__file__'):\n",
      "  File \"/home/pi/.local/lib/python3.7/site-packages/tensorflow/__init__.py\", line 50, in __getattr__\n",
      "    module = self._load()\n",
      "  File \"/home/pi/.local/lib/python3.7/site-packages/tensorflow/__init__.py\", line 44, in _load\n",
      "    module = _importlib.import_module(self.__name__)\n",
      "  File \"/usr/lib/python3.7/importlib/__init__.py\", line 127, in import_module\n",
      "    return _bootstrap._gcd_import(name[level:], package, level)\n",
      "  File \"<frozen importlib._bootstrap>\", line 1006, in _gcd_import\n",
      "  File \"<frozen importlib._bootstrap>\", line 983, in _find_and_load\n",
      "  File \"<frozen importlib._bootstrap>\", line 953, in _find_and_load_unlocked\n",
      "  File \"<frozen importlib._bootstrap>\", line 219, in _call_with_frames_removed\n",
      "  File \"<frozen importlib._bootstrap>\", line 1006, in _gcd_import\n",
      "  File \"<frozen importlib._bootstrap>\", line 983, in _find_and_load\n",
      "  File \"<frozen importlib._bootstrap>\", line 967, in _find_and_load_unlocked\n",
      "  File \"<frozen importlib._bootstrap>\", line 677, in _load_unlocked\n",
      "  File \"<frozen importlib._bootstrap_external>\", line 728, in exec_module\n",
      "  File \"<frozen importlib._bootstrap>\", line 219, in _call_with_frames_removed\n",
      "  File \"/home/pi/.local/lib/python3.7/site-packages/tensorflow_core/__init__.py\", line 34, in <module>\n",
      "    modules/gapi/CMakeFiles/opencv_perf_gapi.dir/perf/perf_main.cpp.o: /usr/include/arm-linux-gnueabihf/bits/pthreadtypes-arch.h\n",
      "ValueError: source code string cannot contain null bytes\n",
      "\n",
      "During handling of the above exception, another exception occurred:\n",
      "\n",
      "Traceback (most recent call last):\n",
      "  File \"/usr/local/lib/python3.7/dist-packages/IPython/core/interactiveshell.py\", line 2886, in _run_cell\n",
      "    return runner(coro)\n",
      "  File \"/usr/local/lib/python3.7/dist-packages/IPython/core/async_helpers.py\", line 68, in _pseudo_sync_runner\n",
      "    coro.send(None)\n",
      "  File \"/usr/local/lib/python3.7/dist-packages/IPython/core/interactiveshell.py\", line 3063, in run_cell_async\n",
      "    interactivity=interactivity, compiler=compiler, result=result)\n",
      "  File \"/usr/local/lib/python3.7/dist-packages/IPython/core/interactiveshell.py\", line 3273, in run_ast_nodes\n",
      "    self.showtraceback()\n",
      "  File \"/usr/local/lib/python3.7/dist-packages/IPython/core/interactiveshell.py\", line 2047, in showtraceback\n",
      "    value, tb, tb_offset=tb_offset)\n",
      "  File \"/usr/local/lib/python3.7/dist-packages/IPython/core/ultratb.py\", line 1415, in structured_traceback\n",
      "    self, etype, value, tb, tb_offset, number_of_lines_of_context)\n",
      "  File \"/usr/local/lib/python3.7/dist-packages/IPython/core/ultratb.py\", line 1315, in structured_traceback\n",
      "    self, etype, value, tb, tb_offset, number_of_lines_of_context\n",
      "  File \"/usr/local/lib/python3.7/dist-packages/IPython/core/ultratb.py\", line 1190, in structured_traceback\n",
      "    chained_exceptions_tb_offset)\n",
      "  File \"/usr/local/lib/python3.7/dist-packages/IPython/core/ultratb.py\", line 1124, in format_exception_as_a_whole\n",
      "    records = self.get_records(etb, number_of_lines_of_context, tb_offset)\n",
      "  File \"/usr/local/lib/python3.7/dist-packages/IPython/core/ultratb.py\", line 1163, in get_records\n",
      "    traceback.print_exc(file=self.ostream)\n",
      "  File \"/usr/lib/python3.7/traceback.py\", line 163, in print_exc\n",
      "    print_exception(*sys.exc_info(), limit=limit, file=file, chain=chain)\n",
      "  File \"/usr/lib/python3.7/traceback.py\", line 104, in print_exception\n"
     ]
    },
    {
     "name": "stderr",
     "output_type": "stream",
     "text": [
      "    type(value), value, tb, limit=limit).format(chain=chain):\n",
      "  File \"/usr/lib/python3.7/traceback.py\", line 508, in __init__\n",
      "    capture_locals=capture_locals)\n",
      "  File \"/usr/lib/python3.7/traceback.py\", line 363, in extract\n",
      "    f.line\n",
      "  File \"/usr/lib/python3.7/traceback.py\", line 285, in line\n",
      "    self._line = linecache.getline(self.filename, self.lineno).strip()\n",
      "  File \"/usr/lib/python3.7/linecache.py\", line 16, in getline\n",
      "    lines = getlines(filename, module_globals)\n",
      "  File \"/usr/lib/python3.7/linecache.py\", line 47, in getlines\n",
      "    return updatecache(filename, module_globals)\n",
      "  File \"/usr/lib/python3.7/linecache.py\", line 137, in updatecache\n",
      "    lines = fp.readlines()\n",
      "  File \"/usr/lib/python3.7/codecs.py\", line 322, in decode\n",
      "    (result, consumed) = self._buffer_decode(data, self.errors, final)\n",
      "UnicodeDecodeError: 'utf-8' codec can't decode byte 0xac in position 4128: invalid start byte\n",
      "\n",
      "During handling of the above exception, another exception occurred:\n",
      "\n",
      "Traceback (most recent call last):\n",
      "  File \"/usr/local/lib/python3.7/dist-packages/IPython/core/interactiveshell.py\", line 2044, in showtraceback\n",
      "    stb = value._render_traceback_()\n",
      "AttributeError: 'UnicodeDecodeError' object has no attribute '_render_traceback_'\n",
      "\n",
      "During handling of the above exception, another exception occurred:\n",
      "\n",
      "Traceback (most recent call last):\n",
      "  File \"/usr/local/lib/python3.7/dist-packages/IPython/core/ultratb.py\", line 1148, in get_records\n",
      "    return _fixed_getinnerframes(etb, number_of_lines_of_context, tb_offset)\n",
      "  File \"/usr/local/lib/python3.7/dist-packages/IPython/core/ultratb.py\", line 316, in wrapped\n",
      "    return f(*args, **kwargs)\n",
      "  File \"/usr/local/lib/python3.7/dist-packages/IPython/core/ultratb.py\", line 350, in _fixed_getinnerframes\n",
      "    records = fix_frame_records_filenames(inspect.getinnerframes(etb, context))\n",
      "  File \"/usr/lib/python3.7/inspect.py\", line 1502, in getinnerframes\n",
      "    frameinfo = (tb.tb_frame,) + getframeinfo(tb, context)\n",
      "  File \"/usr/lib/python3.7/inspect.py\", line 1460, in getframeinfo\n",
      "    filename = getsourcefile(frame) or getfile(frame)\n",
      "  File \"/usr/lib/python3.7/inspect.py\", line 696, in getsourcefile\n",
      "    if getattr(getmodule(object, filename), '__loader__', None) is not None:\n",
      "  File \"/usr/lib/python3.7/inspect.py\", line 733, in getmodule\n",
      "    if ismodule(module) and hasattr(module, '__file__'):\n",
      "  File \"/home/pi/.local/lib/python3.7/site-packages/tensorflow/__init__.py\", line 50, in __getattr__\n",
      "    module = self._load()\n",
      "  File \"/home/pi/.local/lib/python3.7/site-packages/tensorflow/__init__.py\", line 44, in _load\n",
      "    module = _importlib.import_module(self.__name__)\n",
      "  File \"/usr/lib/python3.7/importlib/__init__.py\", line 127, in import_module\n",
      "    return _bootstrap._gcd_import(name[level:], package, level)\n",
      "  File \"<frozen importlib._bootstrap>\", line 1006, in _gcd_import\n",
      "  File \"<frozen importlib._bootstrap>\", line 983, in _find_and_load\n",
      "  File \"<frozen importlib._bootstrap>\", line 953, in _find_and_load_unlocked\n",
      "  File \"<frozen importlib._bootstrap>\", line 219, in _call_with_frames_removed\n",
      "  File \"<frozen importlib._bootstrap>\", line 1006, in _gcd_import\n",
      "  File \"<frozen importlib._bootstrap>\", line 983, in _find_and_load\n",
      "  File \"<frozen importlib._bootstrap>\", line 967, in _find_and_load_unlocked\n",
      "  File \"<frozen importlib._bootstrap>\", line 677, in _load_unlocked\n",
      "  File \"<frozen importlib._bootstrap_external>\", line 728, in exec_module\n",
      "  File \"<frozen importlib._bootstrap>\", line 219, in _call_with_frames_removed\n",
      "  File \"/home/pi/.local/lib/python3.7/site-packages/tensorflow_core/__init__.py\", line 34, in <module>\n",
      "    modules/gapi/CMakeFiles/opencv_perf_gapi.dir/perf/perf_main.cpp.o: /usr/include/arm-linux-gnueabihf/bits/pthreadtypes-arch.h\n",
      "ValueError: source code string cannot contain null bytes\n",
      "\n",
      "During handling of the above exception, another exception occurred:\n",
      "\n",
      "Traceback (most recent call last):\n",
      "  File \"/usr/local/lib/python3.7/dist-packages/ipykernel/kernelbase.py\", line 268, in dispatch_shell\n",
      "    yield gen.maybe_future(handler(stream, idents, msg))\n",
      "  File \"/usr/local/lib/python3.7/dist-packages/tornado/gen.py\", line 735, in run\n",
      "    value = future.result()\n",
      "  File \"/usr/local/lib/python3.7/dist-packages/tornado/gen.py\", line 742, in run\n",
      "    yielded = self.gen.throw(*exc_info)  # type: ignore\n",
      "  File \"/usr/local/lib/python3.7/dist-packages/ipykernel/kernelbase.py\", line 545, in execute_request\n",
      "    user_expressions, allow_stdin,\n",
      "  File \"/usr/local/lib/python3.7/dist-packages/tornado/gen.py\", line 735, in run\n",
      "    value = future.result()\n",
      "  File \"/usr/local/lib/python3.7/dist-packages/tornado/gen.py\", line 209, in wrapper\n",
      "    yielded = next(result)\n",
      "  File \"/usr/local/lib/python3.7/dist-packages/ipykernel/ipkernel.py\", line 300, in do_execute\n",
      "    res = shell.run_cell(code, store_history=store_history, silent=silent)\n",
      "  File \"/usr/local/lib/python3.7/dist-packages/ipykernel/zmqshell.py\", line 536, in run_cell\n",
      "    return super(ZMQInteractiveShell, self).run_cell(*args, **kwargs)\n",
      "  File \"/usr/local/lib/python3.7/dist-packages/IPython/core/interactiveshell.py\", line 2858, in run_cell\n",
      "    raw_cell, store_history, silent, shell_futures)\n",
      "  File \"/usr/local/lib/python3.7/dist-packages/IPython/core/interactiveshell.py\", line 2891, in _run_cell\n",
      "    self.showtraceback(running_compiled_code=True)\n",
      "  File \"/usr/local/lib/python3.7/dist-packages/IPython/core/interactiveshell.py\", line 2047, in showtraceback\n",
      "    value, tb, tb_offset=tb_offset)\n",
      "  File \"/usr/local/lib/python3.7/dist-packages/IPython/core/ultratb.py\", line 1415, in structured_traceback\n",
      "    self, etype, value, tb, tb_offset, number_of_lines_of_context)\n",
      "  File \"/usr/local/lib/python3.7/dist-packages/IPython/core/ultratb.py\", line 1315, in structured_traceback\n",
      "    self, etype, value, tb, tb_offset, number_of_lines_of_context\n",
      "  File \"/usr/local/lib/python3.7/dist-packages/IPython/core/ultratb.py\", line 1190, in structured_traceback\n",
      "    chained_exceptions_tb_offset)\n",
      "  File \"/usr/local/lib/python3.7/dist-packages/IPython/core/ultratb.py\", line 1124, in format_exception_as_a_whole\n",
      "    records = self.get_records(etb, number_of_lines_of_context, tb_offset)\n",
      "  File \"/usr/local/lib/python3.7/dist-packages/IPython/core/ultratb.py\", line 1163, in get_records\n",
      "    traceback.print_exc(file=self.ostream)\n",
      "  File \"/usr/lib/python3.7/traceback.py\", line 163, in print_exc\n",
      "    print_exception(*sys.exc_info(), limit=limit, file=file, chain=chain)\n",
      "  File \"/usr/lib/python3.7/traceback.py\", line 104, in print_exception\n",
      "    type(value), value, tb, limit=limit).format(chain=chain):\n",
      "  File \"/usr/lib/python3.7/traceback.py\", line 508, in __init__\n",
      "    capture_locals=capture_locals)\n",
      "  File \"/usr/lib/python3.7/traceback.py\", line 363, in extract\n",
      "    f.line\n",
      "  File \"/usr/lib/python3.7/traceback.py\", line 285, in line\n",
      "    self._line = linecache.getline(self.filename, self.lineno).strip()\n",
      "  File \"/usr/lib/python3.7/linecache.py\", line 16, in getline\n",
      "    lines = getlines(filename, module_globals)\n",
      "  File \"/usr/lib/python3.7/linecache.py\", line 47, in getlines\n",
      "    return updatecache(filename, module_globals)\n",
      "  File \"/usr/lib/python3.7/linecache.py\", line 137, in updatecache\n",
      "    lines = fp.readlines()\n",
      "  File \"/usr/lib/python3.7/codecs.py\", line 322, in decode\n",
      "    (result, consumed) = self._buffer_decode(data, self.errors, final)\n",
      "UnicodeDecodeError: 'utf-8' codec can't decode byte 0xac in position 4128: invalid start byte\n",
      "\n",
      "During handling of the above exception, another exception occurred:\n",
      "\n",
      "Traceback (most recent call last):\n",
      "  File \"/usr/lib/python3.7/logging/__init__.py\", line 1034, in emit\n",
      "    msg = self.format(record)\n",
      "  File \"/usr/lib/python3.7/logging/__init__.py\", line 880, in format\n",
      "    return fmt.format(record)\n",
      "  File \"/usr/local/lib/python3.7/dist-packages/traitlets/config/application.py\", line 117, in format\n",
      "    return super(LevelFormatter, self).format(record)\n",
      "  File \"/usr/lib/python3.7/logging/__init__.py\", line 627, in format\n",
      "    record.exc_text = self.formatException(record.exc_info)\n",
      "  File \"/usr/lib/python3.7/logging/__init__.py\", line 577, in formatException\n",
      "    traceback.print_exception(ei[0], ei[1], tb, None, sio)\n",
      "  File \"/usr/lib/python3.7/traceback.py\", line 104, in print_exception\n",
      "    type(value), value, tb, limit=limit).format(chain=chain):\n",
      "  File \"/usr/lib/python3.7/traceback.py\", line 521, in __init__\n",
      "    self._load_lines()\n",
      "  File \"/usr/lib/python3.7/traceback.py\", line 533, in _load_lines\n",
      "    self.__context__._load_lines()\n",
      "  File \"/usr/lib/python3.7/traceback.py\", line 531, in _load_lines\n"
     ]
    },
    {
     "name": "stderr",
     "output_type": "stream",
     "text": [
      "    frame.line\n",
      "  File \"/usr/lib/python3.7/traceback.py\", line 285, in line\n",
      "    self._line = linecache.getline(self.filename, self.lineno).strip()\n",
      "  File \"/usr/lib/python3.7/linecache.py\", line 16, in getline\n",
      "    lines = getlines(filename, module_globals)\n",
      "  File \"/usr/lib/python3.7/linecache.py\", line 47, in getlines\n",
      "    return updatecache(filename, module_globals)\n",
      "  File \"/usr/lib/python3.7/linecache.py\", line 137, in updatecache\n",
      "    lines = fp.readlines()\n",
      "  File \"/usr/lib/python3.7/codecs.py\", line 322, in decode\n",
      "    (result, consumed) = self._buffer_decode(data, self.errors, final)\n",
      "UnicodeDecodeError: 'utf-8' codec can't decode byte 0xac in position 4128: invalid start byte\n",
      "\n",
      "During handling of the above exception, another exception occurred:\n",
      "\n",
      "Traceback (most recent call last):\n",
      "  File \"/usr/local/lib/python3.7/dist-packages/ipykernel/kernelbase.py\", line 381, in dispatch_queue\n",
      "    yield self.process_one()\n",
      "  File \"/usr/local/lib/python3.7/dist-packages/tornado/gen.py\", line 735, in run\n",
      "    value = future.result()\n",
      "  File \"/usr/local/lib/python3.7/dist-packages/tornado/gen.py\", line 742, in run\n",
      "    yielded = self.gen.throw(*exc_info)  # type: ignore\n",
      "  File \"/usr/local/lib/python3.7/dist-packages/ipykernel/kernelbase.py\", line 365, in process_one\n",
      "    yield gen.maybe_future(dispatch(*args))\n",
      "  File \"/usr/local/lib/python3.7/dist-packages/tornado/gen.py\", line 735, in run\n",
      "    value = future.result()\n",
      "  File \"/usr/local/lib/python3.7/dist-packages/tornado/gen.py\", line 742, in run\n",
      "    yielded = self.gen.throw(*exc_info)  # type: ignore\n",
      "  File \"/usr/local/lib/python3.7/dist-packages/ipykernel/kernelbase.py\", line 270, in dispatch_shell\n",
      "    self.log.error(\"Exception in message handler:\", exc_info=True)\n",
      "  File \"/usr/lib/python3.7/logging/__init__.py\", line 1412, in error\n",
      "    self._log(ERROR, msg, args, **kwargs)\n",
      "  File \"/usr/lib/python3.7/logging/__init__.py\", line 1519, in _log\n",
      "    self.handle(record)\n",
      "  File \"/usr/lib/python3.7/logging/__init__.py\", line 1529, in handle\n",
      "    self.callHandlers(record)\n",
      "  File \"/usr/lib/python3.7/logging/__init__.py\", line 1591, in callHandlers\n",
      "    hdlr.handle(record)\n",
      "  File \"/usr/lib/python3.7/logging/__init__.py\", line 905, in handle\n",
      "    self.emit(record)\n",
      "  File \"/usr/lib/python3.7/logging/__init__.py\", line 1040, in emit\n",
      "    self.handleError(record)\n",
      "  File \"/usr/lib/python3.7/logging/__init__.py\", line 958, in handleError\n",
      "    traceback.print_exception(t, v, tb, None, sys.stderr)\n",
      "  File \"/usr/lib/python3.7/traceback.py\", line 104, in print_exception\n",
      "    type(value), value, tb, limit=limit).format(chain=chain):\n",
      "  File \"/usr/lib/python3.7/traceback.py\", line 521, in __init__\n",
      "    self._load_lines()\n",
      "  File \"/usr/lib/python3.7/traceback.py\", line 533, in _load_lines\n",
      "    self.__context__._load_lines()\n",
      "  File \"/usr/lib/python3.7/traceback.py\", line 533, in _load_lines\n",
      "    self.__context__._load_lines()\n",
      "  File \"/usr/lib/python3.7/traceback.py\", line 531, in _load_lines\n",
      "    frame.line\n",
      "  File \"/usr/lib/python3.7/traceback.py\", line 285, in line\n",
      "    self._line = linecache.getline(self.filename, self.lineno).strip()\n",
      "  File \"/usr/lib/python3.7/linecache.py\", line 16, in getline\n",
      "    lines = getlines(filename, module_globals)\n",
      "  File \"/usr/lib/python3.7/linecache.py\", line 47, in getlines\n",
      "    return updatecache(filename, module_globals)\n",
      "  File \"/usr/lib/python3.7/linecache.py\", line 137, in updatecache\n",
      "    lines = fp.readlines()\n",
      "  File \"/usr/lib/python3.7/codecs.py\", line 322, in decode\n",
      "    (result, consumed) = self._buffer_decode(data, self.errors, final)\n",
      "UnicodeDecodeError: 'utf-8' codec can't decode byte 0xac in position 4128: invalid start byte\n",
      "\n",
      "During handling of the above exception, another exception occurred:\n",
      "\n",
      "Traceback (most recent call last):\n",
      "  File \"/usr/lib/python3.7/logging/__init__.py\", line 1034, in emit\n",
      "    msg = self.format(record)\n",
      "  File \"/usr/lib/python3.7/logging/__init__.py\", line 880, in format\n",
      "    return fmt.format(record)\n",
      "  File \"/usr/local/lib/python3.7/dist-packages/traitlets/config/application.py\", line 117, in format\n",
      "    return super(LevelFormatter, self).format(record)\n",
      "  File \"/usr/lib/python3.7/logging/__init__.py\", line 627, in format\n",
      "    record.exc_text = self.formatException(record.exc_info)\n",
      "  File \"/usr/lib/python3.7/logging/__init__.py\", line 577, in formatException\n",
      "    traceback.print_exception(ei[0], ei[1], tb, None, sio)\n",
      "  File \"/usr/lib/python3.7/traceback.py\", line 104, in print_exception\n",
      "    type(value), value, tb, limit=limit).format(chain=chain):\n",
      "  File \"/usr/lib/python3.7/traceback.py\", line 521, in __init__\n",
      "    self._load_lines()\n",
      "  File \"/usr/lib/python3.7/traceback.py\", line 533, in _load_lines\n",
      "    self.__context__._load_lines()\n",
      "  File \"/usr/lib/python3.7/traceback.py\", line 533, in _load_lines\n",
      "    self.__context__._load_lines()\n",
      "  File \"/usr/lib/python3.7/traceback.py\", line 533, in _load_lines\n",
      "    self.__context__._load_lines()\n",
      "  File \"/usr/lib/python3.7/traceback.py\", line 531, in _load_lines\n",
      "    frame.line\n",
      "  File \"/usr/lib/python3.7/traceback.py\", line 285, in line\n",
      "    self._line = linecache.getline(self.filename, self.lineno).strip()\n",
      "  File \"/usr/lib/python3.7/linecache.py\", line 16, in getline\n",
      "    lines = getlines(filename, module_globals)\n",
      "  File \"/usr/lib/python3.7/linecache.py\", line 47, in getlines\n",
      "    return updatecache(filename, module_globals)\n",
      "  File \"/usr/lib/python3.7/linecache.py\", line 137, in updatecache\n",
      "    lines = fp.readlines()\n",
      "  File \"/usr/lib/python3.7/codecs.py\", line 322, in decode\n",
      "    (result, consumed) = self._buffer_decode(data, self.errors, final)\n",
      "UnicodeDecodeError: 'utf-8' codec can't decode byte 0xac in position 4128: invalid start byte\n",
      "\n",
      "During handling of the above exception, another exception occurred:\n",
      "\n",
      "Traceback (most recent call last):\n",
      "  File \"/usr/local/lib/python3.7/dist-packages/tornado/ioloop.py\", line 743, in _run_callback\n",
      "    ret = callback()\n",
      "  File \"/usr/local/lib/python3.7/dist-packages/tornado/ioloop.py\", line 767, in _discard_future_result\n",
      "    future.result()\n",
      "  File \"/usr/local/lib/python3.7/dist-packages/tornado/gen.py\", line 742, in run\n",
      "    yielded = self.gen.throw(*exc_info)  # type: ignore\n",
      "  File \"/usr/local/lib/python3.7/dist-packages/ipykernel/kernelbase.py\", line 383, in dispatch_queue\n",
      "    self.log.exception(\"Error in message handler\")\n",
      "  File \"/usr/lib/python3.7/logging/__init__.py\", line 1418, in exception\n",
      "    self.error(msg, *args, exc_info=exc_info, **kwargs)\n",
      "  File \"/usr/lib/python3.7/logging/__init__.py\", line 1412, in error\n",
      "    self._log(ERROR, msg, args, **kwargs)\n",
      "  File \"/usr/lib/python3.7/logging/__init__.py\", line 1519, in _log\n",
      "    self.handle(record)\n",
      "  File \"/usr/lib/python3.7/logging/__init__.py\", line 1529, in handle\n",
      "    self.callHandlers(record)\n",
      "  File \"/usr/lib/python3.7/logging/__init__.py\", line 1591, in callHandlers\n",
      "    hdlr.handle(record)\n",
      "  File \"/usr/lib/python3.7/logging/__init__.py\", line 905, in handle\n",
      "    self.emit(record)\n",
      "  File \"/usr/lib/python3.7/logging/__init__.py\", line 1040, in emit\n",
      "    self.handleError(record)\n",
      "  File \"/usr/lib/python3.7/logging/__init__.py\", line 958, in handleError\n",
      "    traceback.print_exception(t, v, tb, None, sys.stderr)\n",
      "  File \"/usr/lib/python3.7/traceback.py\", line 104, in print_exception\n",
      "    type(value), value, tb, limit=limit).format(chain=chain):\n",
      "  File \"/usr/lib/python3.7/traceback.py\", line 521, in __init__\n",
      "    self._load_lines()\n",
      "  File \"/usr/lib/python3.7/traceback.py\", line 533, in _load_lines\n",
      "    self.__context__._load_lines()\n",
      "  File \"/usr/lib/python3.7/traceback.py\", line 533, in _load_lines\n",
      "    self.__context__._load_lines()\n",
      "  File \"/usr/lib/python3.7/traceback.py\", line 533, in _load_lines\n",
      "    self.__context__._load_lines()\n",
      "  [Previous line repeated 1 more time]\n",
      "  File \"/usr/lib/python3.7/traceback.py\", line 531, in _load_lines\n",
      "    frame.line\n",
      "  File \"/usr/lib/python3.7/traceback.py\", line 285, in line\n",
      "    self._line = linecache.getline(self.filename, self.lineno).strip()\n",
      "  File \"/usr/lib/python3.7/linecache.py\", line 16, in getline\n",
      "    lines = getlines(filename, module_globals)\n",
      "  File \"/usr/lib/python3.7/linecache.py\", line 47, in getlines\n",
      "    return updatecache(filename, module_globals)\n",
      "  File \"/usr/lib/python3.7/linecache.py\", line 137, in updatecache\n",
      "    lines = fp.readlines()\n",
      "  File \"/usr/lib/python3.7/codecs.py\", line 322, in decode\n",
      "    (result, consumed) = self._buffer_decode(data, self.errors, final)\n",
      "UnicodeDecodeError: 'utf-8' codec can't decode byte 0xac in position 4128: invalid start byte\n",
      "\n",
      "During handling of the above exception, another exception occurred:\n",
      "\n",
      "Traceback (most recent call last):\n",
      "  File \"/usr/lib/python3.7/logging/__init__.py\", line 1034, in emit\n"
     ]
    },
    {
     "name": "stderr",
     "output_type": "stream",
     "text": [
      "    msg = self.format(record)\n",
      "  File \"/usr/lib/python3.7/logging/__init__.py\", line 880, in format\n",
      "    return fmt.format(record)\n",
      "  File \"/usr/lib/python3.7/logging/__init__.py\", line 627, in format\n",
      "    record.exc_text = self.formatException(record.exc_info)\n",
      "  File \"/usr/lib/python3.7/logging/__init__.py\", line 577, in formatException\n",
      "    traceback.print_exception(ei[0], ei[1], tb, None, sio)\n",
      "  File \"/usr/lib/python3.7/traceback.py\", line 104, in print_exception\n",
      "    type(value), value, tb, limit=limit).format(chain=chain):\n",
      "  File \"/usr/lib/python3.7/traceback.py\", line 521, in __init__\n",
      "    self._load_lines()\n",
      "  File \"/usr/lib/python3.7/traceback.py\", line 533, in _load_lines\n",
      "    self.__context__._load_lines()\n",
      "  File \"/usr/lib/python3.7/traceback.py\", line 533, in _load_lines\n",
      "    self.__context__._load_lines()\n",
      "  File \"/usr/lib/python3.7/traceback.py\", line 533, in _load_lines\n",
      "    self.__context__._load_lines()\n",
      "  [Previous line repeated 2 more times]\n",
      "  File \"/usr/lib/python3.7/traceback.py\", line 531, in _load_lines\n",
      "    frame.line\n",
      "  File \"/usr/lib/python3.7/traceback.py\", line 285, in line\n",
      "    self._line = linecache.getline(self.filename, self.lineno).strip()\n",
      "  File \"/usr/lib/python3.7/linecache.py\", line 16, in getline\n",
      "    lines = getlines(filename, module_globals)\n",
      "  File \"/usr/lib/python3.7/linecache.py\", line 47, in getlines\n",
      "    return updatecache(filename, module_globals)\n",
      "  File \"/usr/lib/python3.7/linecache.py\", line 137, in updatecache\n",
      "    lines = fp.readlines()\n",
      "  File \"/usr/lib/python3.7/codecs.py\", line 322, in decode\n",
      "    (result, consumed) = self._buffer_decode(data, self.errors, final)\n",
      "UnicodeDecodeError: 'utf-8' codec can't decode byte 0xac in position 4128: invalid start byte\n",
      "\n",
      "During handling of the above exception, another exception occurred:\n",
      "\n",
      "Traceback (most recent call last):\n",
      "  File \"/usr/lib/python3.7/asyncio/events.py\", line 88, in _run\n",
      "    self._context.run(self._callback, *self._args)\n",
      "  File \"/usr/local/lib/python3.7/dist-packages/tornado/ioloop.py\", line 690, in <lambda>\n",
      "    lambda f: self._run_callback(functools.partial(callback, future))\n",
      "  File \"/usr/local/lib/python3.7/dist-packages/tornado/ioloop.py\", line 763, in _run_callback\n",
      "    app_log.error(\"Exception in callback %r\", callback, exc_info=True)\n",
      "  File \"/usr/lib/python3.7/logging/__init__.py\", line 1412, in error\n",
      "    self._log(ERROR, msg, args, **kwargs)\n",
      "  File \"/usr/lib/python3.7/logging/__init__.py\", line 1519, in _log\n",
      "    self.handle(record)\n",
      "  File \"/usr/lib/python3.7/logging/__init__.py\", line 1529, in handle\n",
      "    self.callHandlers(record)\n",
      "  File \"/usr/lib/python3.7/logging/__init__.py\", line 1591, in callHandlers\n",
      "    hdlr.handle(record)\n",
      "  File \"/usr/lib/python3.7/logging/__init__.py\", line 905, in handle\n",
      "    self.emit(record)\n",
      "  File \"/usr/lib/python3.7/logging/__init__.py\", line 1040, in emit\n",
      "    self.handleError(record)\n",
      "  File \"/usr/lib/python3.7/logging/__init__.py\", line 958, in handleError\n",
      "    traceback.print_exception(t, v, tb, None, sys.stderr)\n",
      "  File \"/usr/lib/python3.7/traceback.py\", line 104, in print_exception\n",
      "    type(value), value, tb, limit=limit).format(chain=chain):\n",
      "  File \"/usr/lib/python3.7/traceback.py\", line 521, in __init__\n",
      "    self._load_lines()\n",
      "  File \"/usr/lib/python3.7/traceback.py\", line 533, in _load_lines\n",
      "    self.__context__._load_lines()\n",
      "  File \"/usr/lib/python3.7/traceback.py\", line 533, in _load_lines\n",
      "    self.__context__._load_lines()\n",
      "  File \"/usr/lib/python3.7/traceback.py\", line 533, in _load_lines\n",
      "    self.__context__._load_lines()\n",
      "  [Previous line repeated 3 more times]\n",
      "  File \"/usr/lib/python3.7/traceback.py\", line 531, in _load_lines\n",
      "    frame.line\n",
      "  File \"/usr/lib/python3.7/traceback.py\", line 285, in line\n",
      "    self._line = linecache.getline(self.filename, self.lineno).strip()\n",
      "  File \"/usr/lib/python3.7/linecache.py\", line 16, in getline\n",
      "    lines = getlines(filename, module_globals)\n",
      "  File \"/usr/lib/python3.7/linecache.py\", line 47, in getlines\n",
      "    return updatecache(filename, module_globals)\n",
      "  File \"/usr/lib/python3.7/linecache.py\", line 137, in updatecache\n",
      "    lines = fp.readlines()\n",
      "  File \"/usr/lib/python3.7/codecs.py\", line 322, in decode\n",
      "    (result, consumed) = self._buffer_decode(data, self.errors, final)\n",
      "UnicodeDecodeError: 'utf-8' codec can't decode byte 0xac in position 4128: invalid start byte\n",
      "\n",
      "During handling of the above exception, another exception occurred:\n",
      "\n",
      "Traceback (most recent call last):\n",
      "  File \"/usr/lib/python3.7/logging/__init__.py\", line 1034, in emit\n",
      "    msg = self.format(record)\n",
      "  File \"/usr/lib/python3.7/logging/__init__.py\", line 880, in format\n",
      "    return fmt.format(record)\n",
      "  File \"/usr/lib/python3.7/logging/__init__.py\", line 627, in format\n",
      "    record.exc_text = self.formatException(record.exc_info)\n",
      "  File \"/usr/lib/python3.7/logging/__init__.py\", line 577, in formatException\n",
      "    traceback.print_exception(ei[0], ei[1], tb, None, sio)\n",
      "  File \"/usr/lib/python3.7/traceback.py\", line 104, in print_exception\n",
      "    type(value), value, tb, limit=limit).format(chain=chain):\n",
      "  File \"/usr/lib/python3.7/traceback.py\", line 521, in __init__\n",
      "    self._load_lines()\n",
      "  File \"/usr/lib/python3.7/traceback.py\", line 533, in _load_lines\n",
      "    self.__context__._load_lines()\n",
      "  File \"/usr/lib/python3.7/traceback.py\", line 533, in _load_lines\n",
      "    self.__context__._load_lines()\n",
      "  File \"/usr/lib/python3.7/traceback.py\", line 533, in _load_lines\n",
      "    self.__context__._load_lines()\n",
      "  [Previous line repeated 4 more times]\n",
      "  File \"/usr/lib/python3.7/traceback.py\", line 531, in _load_lines\n",
      "    frame.line\n",
      "  File \"/usr/lib/python3.7/traceback.py\", line 285, in line\n",
      "    self._line = linecache.getline(self.filename, self.lineno).strip()\n",
      "  File \"/usr/lib/python3.7/linecache.py\", line 16, in getline\n",
      "    lines = getlines(filename, module_globals)\n",
      "  File \"/usr/lib/python3.7/linecache.py\", line 47, in getlines\n",
      "    return updatecache(filename, module_globals)\n",
      "  File \"/usr/lib/python3.7/linecache.py\", line 137, in updatecache\n",
      "    lines = fp.readlines()\n",
      "  File \"/usr/lib/python3.7/codecs.py\", line 322, in decode\n",
      "    (result, consumed) = self._buffer_decode(data, self.errors, final)\n",
      "UnicodeDecodeError: 'utf-8' codec can't decode byte 0xac in position 4128: invalid start byte\n",
      "\n",
      "During handling of the above exception, another exception occurred:\n",
      "\n",
      "Traceback (most recent call last):\n",
      "  File \"/usr/lib/python3.7/asyncio/base_events.py\", line 1634, in call_exception_handler\n",
      "    self.default_exception_handler(context)\n",
      "  File \"/usr/lib/python3.7/asyncio/base_events.py\", line 1608, in default_exception_handler\n",
      "    logger.error('\\n'.join(log_lines), exc_info=exc_info)\n",
      "  File \"/usr/lib/python3.7/logging/__init__.py\", line 1412, in error\n",
      "    self._log(ERROR, msg, args, **kwargs)\n",
      "  File \"/usr/lib/python3.7/logging/__init__.py\", line 1519, in _log\n",
      "    self.handle(record)\n",
      "  File \"/usr/lib/python3.7/logging/__init__.py\", line 1529, in handle\n",
      "    self.callHandlers(record)\n",
      "  File \"/usr/lib/python3.7/logging/__init__.py\", line 1591, in callHandlers\n",
      "    hdlr.handle(record)\n",
      "  File \"/usr/lib/python3.7/logging/__init__.py\", line 905, in handle\n",
      "    self.emit(record)\n",
      "  File \"/usr/lib/python3.7/logging/__init__.py\", line 1040, in emit\n",
      "    self.handleError(record)\n",
      "  File \"/usr/lib/python3.7/logging/__init__.py\", line 958, in handleError\n",
      "    traceback.print_exception(t, v, tb, None, sys.stderr)\n",
      "  File \"/usr/lib/python3.7/traceback.py\", line 104, in print_exception\n",
      "    type(value), value, tb, limit=limit).format(chain=chain):\n",
      "  File \"/usr/lib/python3.7/traceback.py\", line 521, in __init__\n",
      "    self._load_lines()\n",
      "  File \"/usr/lib/python3.7/traceback.py\", line 533, in _load_lines\n",
      "    self.__context__._load_lines()\n",
      "  File \"/usr/lib/python3.7/traceback.py\", line 533, in _load_lines\n",
      "    self.__context__._load_lines()\n",
      "  File \"/usr/lib/python3.7/traceback.py\", line 533, in _load_lines\n",
      "    self.__context__._load_lines()\n",
      "  [Previous line repeated 5 more times]\n",
      "  File \"/usr/lib/python3.7/traceback.py\", line 531, in _load_lines\n",
      "    frame.line\n",
      "  File \"/usr/lib/python3.7/traceback.py\", line 285, in line\n",
      "    self._line = linecache.getline(self.filename, self.lineno).strip()\n",
      "  File \"/usr/lib/python3.7/linecache.py\", line 16, in getline\n",
      "    lines = getlines(filename, module_globals)\n",
      "  File \"/usr/lib/python3.7/linecache.py\", line 47, in getlines\n",
      "    return updatecache(filename, module_globals)\n",
      "  File \"/usr/lib/python3.7/linecache.py\", line 137, in updatecache\n",
      "    lines = fp.readlines()\n",
      "  File \"/usr/lib/python3.7/codecs.py\", line 322, in decode\n",
      "    (result, consumed) = self._buffer_decode(data, self.errors, final)\n",
      "UnicodeDecodeError: 'utf-8' codec can't decode byte 0xac in position 4128: invalid start byte\n",
      "\n",
      "During handling of the above exception, another exception occurred:\n",
      "\n",
      "Traceback (most recent call last):\n",
      "  File \"/usr/lib/python3.7/logging/__init__.py\", line 1034, in emit\n",
      "    msg = self.format(record)\n",
      "  File \"/usr/lib/python3.7/logging/__init__.py\", line 880, in format\n",
      "    return fmt.format(record)\n",
      "  File \"/usr/lib/python3.7/logging/__init__.py\", line 627, in format\n",
      "    record.exc_text = self.formatException(record.exc_info)\n",
      "  File \"/usr/lib/python3.7/logging/__init__.py\", line 577, in formatException\n",
      "    traceback.print_exception(ei[0], ei[1], tb, None, sio)\n",
      "  File \"/usr/lib/python3.7/traceback.py\", line 104, in print_exception\n",
      "    type(value), value, tb, limit=limit).format(chain=chain):\n",
      "  File \"/usr/lib/python3.7/traceback.py\", line 521, in __init__\n",
      "    self._load_lines()\n",
      "  File \"/usr/lib/python3.7/traceback.py\", line 533, in _load_lines\n",
      "    self.__context__._load_lines()\n",
      "  File \"/usr/lib/python3.7/traceback.py\", line 533, in _load_lines\n",
      "    self.__context__._load_lines()\n",
      "  File \"/usr/lib/python3.7/traceback.py\", line 533, in _load_lines\n",
      "    self.__context__._load_lines()\n",
      "  [Previous line repeated 6 more times]\n",
      "  File \"/usr/lib/python3.7/traceback.py\", line 531, in _load_lines\n",
      "    frame.line\n",
      "  File \"/usr/lib/python3.7/traceback.py\", line 285, in line\n",
      "    self._line = linecache.getline(self.filename, self.lineno).strip()\n",
      "  File \"/usr/lib/python3.7/linecache.py\", line 16, in getline\n",
      "    lines = getlines(filename, module_globals)\n",
      "  File \"/usr/lib/python3.7/linecache.py\", line 47, in getlines\n",
      "    return updatecache(filename, module_globals)\n",
      "  File \"/usr/lib/python3.7/linecache.py\", line 137, in updatecache\n",
      "    lines = fp.readlines()\n",
      "  File \"/usr/lib/python3.7/codecs.py\", line 322, in decode\n",
      "    (result, consumed) = self._buffer_decode(data, self.errors, final)\n",
      "UnicodeDecodeError: 'utf-8' codec can't decode byte 0xac in position 4128: invalid start byte\n",
      "\n",
      "During handling of the above exception, another exception occurred:\n",
      "\n",
      "Traceback (most recent call last):\n",
      "  File \"/usr/lib/python3.7/runpy.py\", line 193, in _run_module_as_main\n",
      "    \"__main__\", mod_spec)\n",
      "  File \"/usr/lib/python3.7/runpy.py\", line 85, in _run_code\n",
      "    exec(code, run_globals)\n",
      "  File \"/usr/local/lib/python3.7/dist-packages/ipykernel_launcher.py\", line 16, in <module>\n"
     ]
    },
    {
     "name": "stderr",
     "output_type": "stream",
     "text": [
      "    app.launch_new_instance()\n",
      "  File \"/usr/local/lib/python3.7/dist-packages/traitlets/config/application.py\", line 664, in launch_instance\n",
      "    app.start()\n",
      "  File \"/usr/local/lib/python3.7/dist-packages/ipykernel/kernelapp.py\", line 583, in start\n",
      "    self.io_loop.start()\n",
      "  File \"/usr/local/lib/python3.7/dist-packages/tornado/platform/asyncio.py\", line 149, in start\n",
      "    self.asyncio_loop.run_forever()\n",
      "  File \"/usr/lib/python3.7/asyncio/base_events.py\", line 539, in run_forever\n",
      "    self._run_once()\n",
      "  File \"/usr/lib/python3.7/asyncio/base_events.py\", line 1775, in _run_once\n",
      "    handle._run()\n",
      "  File \"/usr/lib/python3.7/asyncio/events.py\", line 100, in _run\n",
      "    self._loop.call_exception_handler(context)\n",
      "  File \"/usr/lib/python3.7/asyncio/base_events.py\", line 1640, in call_exception_handler\n",
      "    exc_info=True)\n",
      "  File \"/usr/lib/python3.7/logging/__init__.py\", line 1412, in error\n",
      "    self._log(ERROR, msg, args, **kwargs)\n",
      "  File \"/usr/lib/python3.7/logging/__init__.py\", line 1519, in _log\n",
      "    self.handle(record)\n",
      "  File \"/usr/lib/python3.7/logging/__init__.py\", line 1529, in handle\n",
      "    self.callHandlers(record)\n",
      "  File \"/usr/lib/python3.7/logging/__init__.py\", line 1591, in callHandlers\n",
      "    hdlr.handle(record)\n",
      "  File \"/usr/lib/python3.7/logging/__init__.py\", line 905, in handle\n",
      "    self.emit(record)\n",
      "  File \"/usr/lib/python3.7/logging/__init__.py\", line 1040, in emit\n",
      "    self.handleError(record)\n",
      "  File \"/usr/lib/python3.7/logging/__init__.py\", line 958, in handleError\n",
      "    traceback.print_exception(t, v, tb, None, sys.stderr)\n",
      "  File \"/usr/lib/python3.7/traceback.py\", line 104, in print_exception\n",
      "    type(value), value, tb, limit=limit).format(chain=chain):\n",
      "  File \"/usr/lib/python3.7/traceback.py\", line 521, in __init__\n",
      "    self._load_lines()\n",
      "  File \"/usr/lib/python3.7/traceback.py\", line 533, in _load_lines\n",
      "    self.__context__._load_lines()\n",
      "  File \"/usr/lib/python3.7/traceback.py\", line 533, in _load_lines\n",
      "    self.__context__._load_lines()\n",
      "  File \"/usr/lib/python3.7/traceback.py\", line 533, in _load_lines\n",
      "    self.__context__._load_lines()\n",
      "  [Previous line repeated 7 more times]\n",
      "  File \"/usr/lib/python3.7/traceback.py\", line 531, in _load_lines\n",
      "    frame.line\n",
      "  File \"/usr/lib/python3.7/traceback.py\", line 285, in line\n",
      "    self._line = linecache.getline(self.filename, self.lineno).strip()\n",
      "  File \"/usr/lib/python3.7/linecache.py\", line 16, in getline\n",
      "    lines = getlines(filename, module_globals)\n",
      "  File \"/usr/lib/python3.7/linecache.py\", line 47, in getlines\n",
      "    return updatecache(filename, module_globals)\n",
      "  File \"/usr/lib/python3.7/linecache.py\", line 137, in updatecache\n",
      "    lines = fp.readlines()\n",
      "  File \"/usr/lib/python3.7/codecs.py\", line 322, in decode\n",
      "    (result, consumed) = self._buffer_decode(data, self.errors, final)\n",
      "UnicodeDecodeError: 'utf-8' codec can't decode byte 0xac in position 4128: invalid start byte\n"
     ]
    }
   ],
   "source": [
    "import sys\n",
    "import time\n",
    "import telepot\n",
    "import os\n",
    "import signal\n",
    "import jsonc\n",
    "\n",
    "import random\n",
    "import nltk\n",
    "from nltk.stem import WordNetLemmatizer\n",
    "lemmatizer = WordNetLemmatizer()\n",
    "import pickle\n",
    "import numpy as np\n",
    "\n",
    "from keras.models import load_model"
   ]
  },
  {
   "cell_type": "code",
   "execution_count": null,
   "metadata": {},
   "outputs": [],
   "source": [
    "model = load_model('chatbot_model.h5')\n",
    "intents = json.loads(open('intents.json').read())\n",
    "words = pickle.load(open('words.pkl','rb'))\n",
    "classes = pickle.load(open('classes.pkl','rb'))"
   ]
  },
  {
   "cell_type": "code",
   "execution_count": null,
   "metadata": {},
   "outputs": [],
   "source": [
    "# return bag of words array: 0 or 1 for each word in the bag that exists in the sentence\n",
    "\n",
    "def clean_up_sentence(sentence):\n",
    "    # tokenize the pattern - split words into array\n",
    "    sentence_words = nltk.word_tokenize(sentence)\n",
    "    # stem each word - create short form for word\n",
    "    sentence_words = [lemmatizer.lemmatize(word.lower()) for word in sentence_words]\n",
    "    return sentence_words"
   ]
  },
  {
   "cell_type": "code",
   "execution_count": null,
   "metadata": {},
   "outputs": [],
   "source": [
    "def bow(sentence, words, show_details=True):\n",
    "    # tokenize the pattern\n",
    "    sentence_words = clean_up_sentence(sentence)\n",
    "    # bag of words - matrix of N words, vocabulary matrix\n",
    "    bag = [0]*len(words)  \n",
    "    for s in sentence_words:\n",
    "        for i,w in enumerate(words):\n",
    "            if w == s: \n",
    "                # assign 1 if current word is in the vocabulary position\n",
    "                bag[i] = 1\n",
    "                if show_details:\n",
    "                    print (\"found in bag: %s\" % w)\n",
    "    return(np.array(bag))"
   ]
  },
  {
   "cell_type": "code",
   "execution_count": null,
   "metadata": {},
   "outputs": [],
   "source": [
    "def predict_class(sentence, model):\n",
    "    # filter out predictions below a threshold\n",
    "    p = bow(sentence, words,show_details=False)\n",
    "    res = model.predict(np.array([p]))[0]\n",
    "    ERROR_THRESHOLD = 0.25\n",
    "    results = [[i,r] for i,r in enumerate(res) if r>ERROR_THRESHOLD]\n",
    "    # sort by strength of probability\n",
    "    results.sort(key=lambda x: x[1], reverse=True)\n",
    "    return_list = []\n",
    "    for r in results:\n",
    "        return_list.append({\"intent\": classes[r[0]], \"probability\": str(r[1])})\n",
    "    return return_list"
   ]
  },
  {
   "cell_type": "code",
   "execution_count": null,
   "metadata": {},
   "outputs": [],
   "source": [
    "def getResponse(ints, intents_json):\n",
    "    tag = ints[0]['intent']\n",
    "    list_of_intents = intents_json['intents']\n",
    "    for i in list_of_intents:\n",
    "        if(i['tag']== tag):\n",
    "            result = random.choice(i['responses'])\n",
    "            break\n",
    "    return result"
   ]
  },
  {
   "cell_type": "code",
   "execution_count": null,
   "metadata": {},
   "outputs": [],
   "source": [
    "def chatbot_response(msg):\n",
    "    ints = predict_class(msg, model)\n",
    "    res = getResponse(ints, intents)\n",
    "    return res"
   ]
  },
  {
   "cell_type": "code",
   "execution_count": 27,
   "metadata": {},
   "outputs": [
    {
     "data": {
      "text/plain": [
       "<telepot.Bot at 0x72a9a590>"
      ]
     },
     "execution_count": 27,
     "metadata": {},
     "output_type": "execute_result"
    }
   ],
   "source": [
    "with open('key.json', 'r') as json_file:\n",
    "    API_KEY = json.loads(json_file.read()) \n",
    "bot = telepot.Bot(API_KEY['id'])\n",
    "bot"
   ]
  },
  {
   "cell_type": "code",
   "execution_count": 3,
   "metadata": {},
   "outputs": [
    {
     "data": {
      "text/plain": [
       "{'id': 565272379,\n",
       " 'is_bot': True,\n",
       " 'first_name': 'Testbot',\n",
       " 'username': 'Zalozhn1k_bot',\n",
       " 'can_join_groups': True,\n",
       " 'can_read_all_group_messages': False,\n",
       " 'supports_inline_queries': False}"
      ]
     },
     "execution_count": 3,
     "metadata": {},
     "output_type": "execute_result"
    }
   ],
   "source": [
    "info = bot.getMe()\n",
    "info"
   ]
  },
  {
   "cell_type": "code",
   "execution_count": 4,
   "metadata": {},
   "outputs": [
    {
     "name": "stdout",
     "output_type": "stream",
     "text": [
      "I am listening...\n",
      "Got command: exit\n",
      "exit\n"
     ]
    }
   ],
   "source": [
    "def on():\n",
    "        return 'On: ok'\n",
    "def off():\n",
    "        return 'Off: ok'\n",
    "def photo():\n",
    "        return \"photo: ok\"\n",
    "\n",
    "def handle(msg):\n",
    "    chat_id = msg['chat']['id']\n",
    "    command = msg['text'].lower()\n",
    "\n",
    "    print('Got command: %s' % command)\n",
    "\n",
    "    if command == 'exit': \n",
    "        bot.sendMessage(chat_id, os.getpid())\n",
    "        print ('exit')\n",
    "        time.sleep(1)\n",
    "        os.kill(os.getpid(), signal.SIGKILL)\n",
    "    elif command == 'on':\n",
    "       bot.sendMessage(chat_id, on())\n",
    "    elif command =='off':\n",
    "       bot.sendMessage(chat_id, off())\n",
    "    elif command =='photo':\n",
    "        bot.sendMessage(chat_id, photo())\n",
    "        os.system('fswebcam -r 1280x720 image.jpg')\n",
    "        bot.sendPhoto(chat_id, open('image.jpg', 'rb'))\n",
    "    else:\n",
    "        res = chatbot_response(command)\n",
    "        bot.sendMessage(chat_id, res)\n",
    "\n",
    "bot = telepot.Bot(API_KEY['id'])\n",
    "bot.message_loop(handle)\n",
    "print('I am listening...')\n"
   ]
  }
 ],
 "metadata": {
  "kernelspec": {
   "display_name": "Python 3",
   "language": "python",
   "name": "python3"
  },
  "language_info": {
   "codemirror_mode": {
    "name": "ipython",
    "version": 3
   },
   "file_extension": ".py",
   "mimetype": "text/x-python",
   "name": "python",
   "nbconvert_exporter": "python",
   "pygments_lexer": "ipython3",
   "version": "3.7.3"
  }
 },
 "nbformat": 4,
 "nbformat_minor": 4
}
